Workbook

Sheet Q1 2025
A1: Evenement | B1: Artikelnr | C1: Omschrijving | D1: Besteld | E1: Stuksprijs | F1: Brutobedrag | G1: Bruto - Rel.korting | H1: Relatiekorting percentage | I1: Groep | J1: Artikelprijs | K1: Vergelijk | L1: Provisie | M1: Prijstype | N1: Prijs 2 | O1: Brutobedrag 2 | P1: Bruto-Rel. korting 2
A2: 4AM Festival.xls | B2: 5021001 | C2: Stroomaansl. 3kW + WCD + Verbruik 1d | D2: 2 | E2: 154.5 | F2: 309 | G2: 278.1 | H2: 10 | I2: =_xlfn.XLOOKUP(Q1_2025[[#This Row],[Artikelnr]],Artikel_prijzen[Artnr],Artikel_prijzen[Groep],"") -> Elektra | J2: =_xlfn.XLOOKUP(Q1_2025[[#This Row],[Artikelnr]],Artikel_prijzen[Artnr],Artikel_prijzen[Prijs 2025],"") -> 106.8625 | K2: =IF(Q1_2025[[#This Row],[Artikelprijs]]<>"",IF(Q1_2025[[#This Row],[Stuksprijs]]=Q1_2025[[#This Row],[Artikelprijs]],"Prijs gelijk","Prijs wijkt af"),"") -> Prijs wijkt af | M2: Stuksprijs | N2: =IF(Q1_2025[[#This Row],[Prijstype]]="Artikelprijs",Q1_2025[[#This Row],[Artikelprijs]],Q1_2025[[#This Row],[Stuksprijs]]) -> 154.5 | O2: =IF(Q1_2025[[#This Row],[Prijstype]]="Artikelprijs",Q1_2025[[#This Row],[Artikelprijs]] * Q1_2025[[#This Row],[Besteld]],Q1_2025[[#This Row],[Brutobedrag]]) -> 309 | P2: =IF(Q1_2025[[#This Row],[Prijstype]] = "Artikelprijs",Q1_2025[[#This Row],[Brutobedrag 2]]*(100-Q1_2025[[#This Row],[Relatiekorting percentage]])/100,Q1_2025[[#This Row],[Bruto - Rel.korting]]) -> 278.1
A3: 4AM Festival.xls | B3: 5021001 | C3: Stroomaansl. 3kW + WCD + Verbruik 1d | D3: 1 | E3: 154.5 | F3: 154.5 | G3: 139.05 | H3: 10 | I3: =_xlfn.XLOOKUP(Q1_2025[[#This Row],[Artikelnr]],Artikel_prijzen[Artnr],Artikel_prijzen[Groep],"") -> Elektra | J3: =_xlfn.XLOOKUP(Q1_2025[[#This Row],[Artikelnr]],Artikel_prijzen[Artnr],Artikel_prijzen[Prijs 2025],"") -> 106.8625 | K3: =IF(Q1_2025[[#This Row],[Artikelprijs]]<>"",IF(Q1_2025[[#This Row],[Stuksprijs]]=Q1_2025[[#This Row],[Artikelprijs]],"Prijs gelijk","Prijs wijkt af"),"") -> Prijs wijkt af | M3: Stuksprijs | N3: =IF(Q1_2025[[#This Row],[Prijstype]]="Artikelprijs",Q1_2025[[#This Row],[Artikelprijs]],Q1_2025[[#This Row],[Stuksprijs]]) -> 154.5 | O3: =IF(Q1_2025[[#This Row],[Prijstype]]="Artikelprijs",Q1_2025[[#This Row],[Artikelprijs]] * Q1_2025[[#This Row],[Besteld]],Q1_2025[[#This Row],[Brutobedrag]]) -> 154.5 | P3: =IF(Q1_2025[[#This Row],[Prijstype]] = "Artikelprijs",Q1_2025[[#This Row],[Brutobedrag 2]]*(100-Q1_2025[[#This Row],[Relatiekorting percentage]])/100,Q1_2025[[#This Row],[Bruto - Rel.korting]]) -> 139.05
A4: AAO 2025.xls | B4: 5031053 | C4: Prolyte truss H30V 3 meter alu | D4: 34 | E4: 113.3 | F4: 3852.2 | G4: 2696.54 | H4: 30 | I4: =_xlfn.XLOOKUP(Q1_2025[[#This Row],[Artikelnr]],Artikel_prijzen[Artnr],Artikel_prijzen[Groep],"") | J4: =_xlfn.XLOOKUP(Q1_2025[[#This Row],[Artikelnr]],Artikel_prijzen[Artnr],Artikel_prijzen[Prijs 2025],"") | K4: =IF(Q1_2025[[#This Row],[Artikelprijs]]<>"",IF(Q1_2025[[#This Row],[Stuksprijs]]=Q1_2025[[#This Row],[Artikelprijs]],"Prijs gelijk","Prijs wijkt af"),"") | N4: =IF(Q1_2025[[#This Row],[Prijstype]]="Artikelprijs",Q1_2025[[#This Row],[Artikelprijs]],Q1_2025[[#This Row],[Stuksprijs]]) -> 113.3 | O4: =IF(Q1_2025[[#This Row],[Prijstype]]="Artikelprijs",Q1_2025[[#This Row],[Artikelprijs]] * Q1_2025[[#This Row],[Besteld]],Q1_2025[[#This Row],[Brutobedrag]]) -> 3852.2 | P4: =IF(Q1_2025[[#This Row],[Prijstype]] = "Artikelprijs",Q1_2025[[#This Row],[Brutobedrag 2]]*(100-Q1_2025[[#This Row],[Relatiekorting percentage]])/100,Q1_2025[[#This Row],[Bruto - Rel.korting]]) -> 2696.54
A5: AAO 2025.xls | B5: 5031052 | C5: Prolyte truss H30V 2 meter alu | D5: 5 | E5: 88.07 | F5: 440.35 | G5: 308.24 | H5: 30 | I5: =_xlfn.XLOOKUP(Q1_2025[[#This Row],[Artikelnr]],Artikel_prijzen[Artnr],Artikel_prijzen[Groep],"") | J5: =_xlfn.XLOOKUP(Q1_2025[[#This Row],[Artikelnr]],Artikel_prijzen[Artnr],Artikel_prijzen[Prijs 2025],"") | K5: =IF(Q1_2025[[#This Row],[Artikelprijs]]<>"",IF(Q1_2025[[#This Row],[Stuksprijs]]=Q1_2025[[#This Row],[Artikelprijs]],"Prijs gelijk","Prijs wijkt af"),"") | N5: =IF(Q1_2025[[#This Row],[Prijstype]]="Artikelprijs",Q1_2025[[#This Row],[Artikelprijs]],Q1_2025[[#This Row],[Stuksprijs]]) -> 88.07 | O5: =IF(Q1_2025[[#This Row],[Prijstype]]="Artikelprijs",Q1_2025[[#This Row],[Artikelprijs]] * Q1_2025[[#This Row],[Besteld]],Q1_2025[[#This Row],[Brutobedrag]]) -> 440.35 | P5: =IF(Q1_2025[[#This Row],[Prijstype]] = "Artikelprijs",Q1_2025[[#This Row],[Brutobedrag 2]]*(100-Q1_2025[[#This Row],[Relatiekorting percentage]])/100,Q1_2025[[#This Row],[Bruto - Rel.korting]]) -> 308.24
A6: AAO 2025.xls | B6: 5031049 | C6: Prolyte truss H30V 0,5 meter alu | D6: 1 | E6: 35.02 | F6: 35.02 | G6: 24.51 | H6: 30 | I6: =_xlfn.XLOOKUP(Q1_2025[[#This Row],[Artikelnr]],Artikel_prijzen[Artnr],Artikel_prijzen[Groep],"") | J6: =_xlfn.XLOOKUP(Q1_2025[[#This Row],[Artikelnr]],Artikel_prijzen[Artnr],Artikel_prijzen[Prijs 2025],"") | K6: =IF(Q1_2025[[#This Row],[Artikelprijs]]<>"",IF(Q1_2025[[#This Row],[Stuksprijs]]=Q1_2025[[#This Row],[Artikelprijs]],"Prijs gelijk","Prijs wijkt af"),"") | N6: =IF(Q1_2025[[#This Row],[Prijstype]]="Artikelprijs",Q1_2025[[#This Row],[Artikelprijs]],Q1_2025[[#This Row],[Stuksprijs]]) -> 35.02 | O6: =IF(Q1_2025[[#This Row],[Prijstype]]="Artikelprijs",Q1_2025[[#This Row],[Artikelprijs]] * Q1_2025[[#This Row],[Besteld]],Q1_2025[[#This Row],[Brutobedrag]]) -> 35.02 | P6: =IF(Q1_2025[[#This Row],[Prijstype]] = "Artikelprijs",Q1_2025[[#This Row],[Brutobedrag 2]]*(100-Q1_2025[[#This Row],[Relatiekorting percentage]])/100,Q1_2025[[#This Row],[Bruto - Rel.korting]]) -> 24.51
A7: AAO 2025.xls | B7: 5031056 | C7: Prolyte truss H30V Hoek V003 alu | D7: 3 | E7: 69.78 | F7: 209.34 | G7: 146.54 | H7: 30 | I7: =_xlfn.XLOOKUP(Q1_2025[[#This Row],[Artikelnr]],Artikel_prijzen[Artnr],Artikel_prijzen[Groep],"") | J7: =_xlfn.XLOOKUP(Q1_2025[[#This Row],[Artikelnr]],Artikel_prijzen[Artnr],Artikel_prijzen[Prijs 2025],"") | K7: =IF(Q1_2025[[#This Row],[Artikelprijs]]<>"",IF(Q1_2025[[#This Row],[Stuksprijs]]=Q1_2025[[#This Row],[Artikelprijs]],"Prijs gelijk","Prijs wijkt af"),"") | N7: =IF(Q1_2025[[#This Row],[Prijstype]]="Artikelprijs",Q1_2025[[#This Row],[Artikelprijs]],Q1_2025[[#This Row],[Stuksprijs]]) -> 69.78 | O7: =IF(Q1_2025[[#This Row],[Prijstype]]="Artikelprijs",Q1_2025[[#This Row],[Artikelprijs]] * Q1_2025[[#This Row],[Besteld]],Q1_2025[[#This Row],[Brutobedrag]]) -> 209.34 | P7: =IF(Q1_2025[[#This Row],[Prijstype]] = "Artikelprijs",Q1_2025[[#This Row],[Brutobedrag 2]]*(100-Q1_2025[[#This Row],[Relatiekorting percentage]])/100,Q1_2025[[#This Row],[Bruto - Rel.korting]]) -> 146.54
A8: AAO 2025.xls | B8: 5031059 | C8: Prolyte truss H30V Hoek V017 alu | D8: 1 | E8: 69.78 | F8: 69.78 | G8: 48.85 | H8: 30 | I8: =_xlfn.XLOOKUP(Q1_2025[[#This Row],[Artikelnr]],Artikel_prijzen[Artnr],Artikel_prijzen[Groep],"") | J8: =_xlfn.XLOOKUP(Q1_2025[[#This Row],[Artikelnr]],Artikel_prijzen[Artnr],Artikel_prijzen[Prijs 2025],"") | K8: =IF(Q1_2025[[#This Row],[Artikelprijs]]<>"",IF(Q1_2025[[#This Row],[Stuksprijs]]=Q1_2025[[#This Row],[Artikelprijs]],"Prijs gelijk","Prijs wijkt af"),"") | N8: =IF(Q1_2025[[#This Row],[Prijstype]]="Artikelprijs",Q1_2025[[#This Row],[Artikelprijs]],Q1_2025[[#This Row],[Stuksprijs]]) -> 69.78 | O8: =IF(Q1_2025[[#This Row],[Prijstype]]="Artikelprijs",Q1_2025[[#This Row],[Artikelprijs]] * Q1_2025[[#This Row],[Besteld]],Q1_2025[[#This Row],[Brutobedrag]]) -> 69.78 | P8: =IF(Q1_2025[[#This Row],[Prijstype]] = "Artikelprijs",Q1_2025[[#This Row],[Brutobedrag 2]]*(100-Q1_2025[[#This Row],[Relatiekorting percentage]])/100,Q1_2025[[#This Row],[Bruto - Rel.korting]]) -> 48.85
A9: AAO 2025.xls | B9: 5030229 | C9: Motortakel incl. ophangpunt + montage max 250kg | D9: 13 | E9: 303.85 | F9: 3950.05 | G9: 2765.03 | H9: 30 | I9: =_xlfn.XLOOKUP(Q1_2025[[#This Row],[Artikelnr]],Artikel_prijzen[Artnr],Artikel_prijzen[Groep],"") -> Rigging | J9: =_xlfn.XLOOKUP(Q1_2025[[#This Row],[Artikelnr]],Artikel_prijzen[Artnr],Artikel_prijzen[Prijs 2025],"") -> 295 | K9: =IF(Q1_2025[[#This Row],[Artikelprijs]]<>"",IF(Q1_2025[[#This Row],[Stuksprijs]]=Q1_2025[[#This Row],[Artikelprijs]],"Prijs gelijk","Prijs wijkt af"),"") -> Prijs wijkt af | M9: Artikelprijs | N9: =IF(Q1_2025[[#This Row],[Prijstype]]="Artikelprijs",Q1_2025[[#This Row],[Artikelprijs]],Q1_2025[[#This Row],[Stuksprijs]]) -> 295 | O9: =IF(Q1_2025[[#This Row],[Prijstype]]="Artikelprijs",Q1_2025[[#This Row],[Artikelprijs]] * Q1_2025[[#This Row],[Besteld]],Q1_2025[[#This Row],[Brutobedrag]]) -> 3835 | P9: =IF(Q1_2025[[#This Row],[Prijstype]] = "Artikelprijs",Q1_2025[[#This Row],[Brutobedrag 2]]*(100-Q1_2025[[#This Row],[Relatiekorting percentage]])/100,Q1_2025[[#This Row],[Bruto - Rel.korting]]) -> 2684.5
A10: AAO 2025.xls | B10: 3098001 | C10: Floodlight HQI - 2000W Asym. | D10: 20 | E10: 285 | F10: 5700 | G10: 4275 | H10: 25 | I10: =_xlfn.XLOOKUP(Q1_2025[[#This Row],[Artikelnr]],Artikel_prijzen[Artnr],Artikel_prijzen[Groep],"") | J10: =_xlfn.XLOOKUP(Q1_2025[[#This Row],[Artikelnr]],Artikel_prijzen[Artnr],Artikel_prijzen[Prijs 2025],"") | K10: =IF(Q1_2025[[#This Row],[Artikelprijs]]<>"",IF(Q1_2025[[#This Row],[Stuksprijs]]=Q1_2025[[#This Row],[Artikelprijs]],"Prijs gelijk","Prijs wijkt af"),"") | N10: =IF(Q1_2025[[#This Row],[Prijstype]]="Artikelprijs",Q1_2025[[#This Row],[Artikelprijs]],Q1_2025[[#This Row],[Stuksprijs]]) -> 285 | O10: =IF(Q1_2025[[#This Row],[Prijstype]]="Artikelprijs",Q1_2025[[#This Row],[Artikelprijs]] * Q1_2025[[#This Row],[Besteld]],Q1_2025[[#This Row],[Brutobedrag]]) -> 5700 | P10: =IF(Q1_2025[[#This Row],[Prijstype]] = "Artikelprijs",Q1_2025[[#This Row],[Brutobedrag 2]]*(100-Q1_2025[[#This Row],[Relatiekorting percentage]])/100,Q1_2025[[#This Row],[Bruto - Rel.korting]]) -> 4275
A11: AAO 2025.xls | B11: 5030229 | C11: Motortakel incl. ophangpunt + montage max 250kg | D11: 4 | E11: 303.85 | F11: 1215.4 | G11: 850.78 | H11: 30 | I11: =_xlfn.XLOOKUP(Q1_2025[[#This Row],[Artikelnr]],Artikel_prijzen[Artnr],Artikel_prijzen[Groep],"") -> Rigging | J11: =_xlfn.XLOOKUP(Q1_2025[[#This Row],[Artikelnr]],Artikel_prijzen[Artnr],Artikel_prijzen[Prijs 2025],"") -> 295 | K11: =IF(Q1_2025[[#This Row],[Artikelprijs]]<>"",IF(Q1_2025[[#This Row],[Stuksprijs]]=Q1_2025[[#This Row],[Artikelprijs]],"Prijs gelijk","Prijs wijkt af"),"") -> Prijs wijkt af | M11: Artikelprijs | N11: =IF(Q1_2025[[#This Row],[Prijstype]]="Artikelprijs",Q1_2025[[#This Row],[Artikelprijs]],Q1_2025[[#This Row],[Stuksprijs]]) -> 295 | O11: =IF(Q1_2025[[#This Row],[Prijstype]]="Artikelprijs",Q1_2025[[#This Row],[Artikelprijs]] * Q1_2025[[#This Row],[Besteld]],Q1_2025[[#This Row],[Brutobedrag]]) -> 1180 | P11: =IF(Q1_2025[[#This Row],[Prijstype]] = "Artikelprijs",Q1_2025[[#This Row],[Brutobedrag 2]]*(100-Q1_2025[[#This Row],[Relatiekorting percentage]])/100,Q1_2025[[#This Row],[Bruto - Rel.korting]]) -> 826
A12: AAO 2025.xls | B12: 5031053 | C12: Prolyte truss H30V 3 meter alu | D12: 20 | E12: 113.3 | F12: 2266 | G12: 1586.2 | H12: 30 | I12: =_xlfn.XLOOKUP(Q1_2025[[#This Row],[Artikelnr]],Artikel_prijzen[Artnr],Artikel_prijzen[Groep],"") | J12: =_xlfn.XLOOKUP(Q1_2025[[#This Row],[Artikelnr]],Artikel_prijzen[Artnr],Artikel_prijzen[Prijs 2025],"") | K12: =IF(Q1_2025[[#This Row],[Artikelprijs]]<>"",IF(Q1_2025[[#This Row],[Stuksprijs]]=Q1_2025[[#This Row],[Artikelprijs]],"Prijs gelijk","Prijs wijkt af"),"") | N12: =IF(Q1_2025[[#This Row],[Prijstype]]="Artikelprijs",Q1_2025[[#This Row],[Artikelprijs]],Q1_2025[[#This Row],[Stuksprijs]]) -> 113.3 | O12: =IF(Q1_2025[[#This Row],[Prijstype]]="Artikelprijs",Q1_2025[[#This Row],[Artikelprijs]] * Q1_2025[[#This Row],[Besteld]],Q1_2025[[#This Row],[Brutobedrag]]) -> 2266 | P12: =IF(Q1_2025[[#This Row],[Prijstype]] = "Artikelprijs",Q1_2025[[#This Row],[Brutobedrag 2]]*(100-Q1_2025[[#This Row],[Relatiekorting percentage]])/100,Q1_2025[[#This Row],[Bruto - Rel.korting]]) -> 1586.2
A13: AAO 2025.xls | B13: 5031052 | C13: Prolyte truss H30V 2 meter alu | D13: 2 | E13: 88.07 | F13: 176.14 | G13: 123.3 | H13: 30 | I13: =_xlfn.XLOOKUP(Q1_2025[[#This Row],[Artikelnr]],Artikel_prijzen[Artnr],Artikel_prijzen[Groep],"") | J13: =_xlfn.XLOOKUP(Q1_2025[[#This Row],[Artikelnr]],Artikel_prijzen[Artnr],Artikel_prijzen[Prijs 2025],"") | K13: =IF(Q1_2025[[#This Row],[Artikelprijs]]<>"",IF(Q1_2025[[#This Row],[Stuksprijs]]=Q1_2025[[#This Row],[Artikelprijs]],"Prijs gelijk","Prijs wijkt af"),"") | N13: =IF(Q1_2025[[#This Row],[Prijstype]]="Artikelprijs",Q1_2025[[#This Row],[Artikelprijs]],Q1_2025[[#This Row],[Stuksprijs]]) -> 88.07 | O13: =IF(Q1_2025[[#This Row],[Prijstype]]="Artikelprijs",Q1_2025[[#This Row],[Artikelprijs]] * Q1_2025[[#This Row],[Besteld]],Q1_2025[[#This Row],[Brutobedrag]]) -> 176.14 | P13: =IF(Q1_2025[[#This Row],[Prijstype]] = "Artikelprijs",Q1_2025[[#This Row],[Brutobedrag 2]]*(100-Q1_2025[[#This Row],[Relatiekorting percentage]])/100,Q1_2025[[#This Row],[Bruto - Rel.korting]]) -> 123.3
A14: AAO 2025.xls | B14: 5030229 | C14: Motortakel incl. ophangpunt + montage max 250kg | D14: 8 | E14: 303.85 | F14: 2430.8 | G14: 1701.56 | H14: 30 | I14: =_xlfn.XLOOKUP(Q1_2025[[#This Row],[Artikelnr]],Artikel_prijzen[Artnr],Artikel_prijzen[Groep],"") -> Rigging | J14: =_xlfn.XLOOKUP(Q1_2025[[#This Row],[Artikelnr]],Artikel_prijzen[Artnr],Artikel_prijzen[Prijs 2025],"") -> 295 | K14: =IF(Q1_2025[[#This Row],[Artikelprijs]]<>"",IF(Q1_2025[[#This Row],[Stuksprijs]]=Q1_2025[[#This Row],[Artikelprijs]],"Prijs gelijk","Prijs wijkt af"),"") -> Prijs wijkt af | M14: Artikelprijs | N14: =IF(Q1_2025[[#This Row],[Prijstype]]="Artikelprijs",Q1_2025[[#This Row],[Artikelprijs]],Q1_2025[[#This Row],[Stuksprijs]]) -> 295 | O14: =IF(Q1_2025[[#This Row],[Prijstype]]="Artikelprijs",Q1_2025[[#This Row],[Artikelprijs]] * Q1_2025[[#This Row],[Besteld]],Q1_2025[[#This Row],[Brutobedrag]]) -> 2360 | P14: =IF(Q1_2025[[#This Row],[Prijstype]] = "Artikelprijs",Q1_2025[[#This Row],[Brutobedrag 2]]*(100-Q1_2025[[#This Row],[Relatiekorting percentage]])/100,Q1_2025[[#This Row],[Bruto - Rel.korting]]) -> 1652
A15: AAO 2025.xls | B15: 2098001 | C15: Gordijnen 3 x 8 mtr. | D15: 25 | E15: 91 | F15: 2275 | G15: 1592.5 | H15: 30 | I15: =_xlfn.XLOOKUP(Q1_2025[[#This Row],[Artikelnr]],Artikel_prijzen[Artnr],Artikel_prijzen[Groep],"") | J15: =_xlfn.XLOOKUP(Q1_2025[[#This Row],[Artikelnr]],Artikel_prijzen[Artnr],Artikel_prijzen[Prijs 2025],"") | K15: =IF(Q1_2025[[#This Row],[Artikelprijs]]<>"",IF(Q1_2025[[#This Row],[Stuksprijs]]=Q1_2025[[#This Row],[Artikelprijs]],"Prijs gelijk","Prijs wijkt af"),"") | N15: =IF(Q1_2025[[#This Row],[Prijstype]]="Artikelprijs",Q1_2025[[#This Row],[Artikelprijs]],Q1_2025[[#This Row],[Stuksprijs]]) -> 91 | O15: =IF(Q1_2025[[#This Row],[Prijstype]]="Artikelprijs",Q1_2025[[#This Row],[Artikelprijs]] * Q1_2025[[#This Row],[Besteld]],Q1_2025[[#This Row],[Brutobedrag]]) -> 2275 | P15: =IF(Q1_2025[[#This Row],[Prijstype]] = "Artikelprijs",Q1_2025[[#This Row],[Brutobedrag 2]]*(100-Q1_2025[[#This Row],[Relatiekorting percentage]])/100,Q1_2025[[#This Row],[Bruto - Rel.korting]]) -> 1592.5
A16: AAO 2025.xls | B16: 2098001 | C16: Gordijnen 3 x 6 mtr. | D16: 4 | E16: 65 | F16: 260 | G16: 182 | H16: 30 | I16: =_xlfn.XLOOKUP(Q1_2025[[#This Row],[Artikelnr]],Artikel_prijzen[Artnr],Artikel_prijzen[Groep],"") | J16: =_xlfn.XLOOKUP(Q1_2025[[#This Row],[Artikelnr]],Artikel_prijzen[Artnr],Artikel_prijzen[Prijs 2025],"") | K16: =IF(Q1_2025[[#This Row],[Artikelprijs]]<>"",IF(Q1_2025[[#This Row],[Stuksprijs]]=Q1_2025[[#This Row],[Artikelprijs]],"Prijs gelijk","Prijs wijkt af"),"") | N16: =IF(Q1_2025[[#This Row],[Prijstype]]="Artikelprijs",Q1_2025[[#This Row],[Artikelprijs]],Q1_2025[[#This Row],[Stuksprijs]]) -> 65 | O16: =IF(Q1_2025[[#This Row],[Prijstype]]="Artikelprijs",Q1_2025[[#This Row],[Artikelprijs]] * Q1_2025[[#This Row],[Besteld]],Q1_2025[[#This Row],[Brutobedrag]]) -> 260 | P16: =IF(Q1_2025[[#This Row],[Prijstype]] = "Artikelprijs",Q1_2025[[#This Row],[Brutobedrag 2]]*(100-Q1_2025[[#This Row],[Relatiekorting percentage]])/100,Q1_2025[[#This Row],[Bruto - Rel.korting]]) -> 182
A17: AAO 2025.xls | B17: 5301001 | C17: Transport vice versa | D17: 2 | E17: 228 | F17: 456 | G17: 456 | H17: 0 | I17: =_xlfn.XLOOKUP(Q1_2025[[#This Row],[Artikelnr]],Artikel_prijzen[Artnr],Artikel_prijzen[Groep],"") | J17: =_xlfn.XLOOKUP(Q1_2025[[#This Row],[Artikelnr]],Artikel_prijzen[Artnr],Artikel_prijzen[Prijs 2025],"") | K17: =IF(Q1_2025[[#This Row],[Artikelprijs]]<>"",IF(Q1_2025[[#This Row],[Stuksprijs]]=Q1_2025[[#This Row],[Artikelprijs]],"Prijs gelijk","Prijs wijkt af"),"") | N17: =IF(Q1_2025[[#This Row],[Prijstype]]="Artikelprijs",Q1_2025[[#This Row],[Artikelprijs]],Q1_2025[[#This Row],[Stuksprijs]]) -> 228 | O17: =IF(Q1_2025[[#This Row],[Prijstype]]="Artikelprijs",Q1_2025[[#This Row],[Artikelprijs]] * Q1_2025[[#This Row],[Besteld]],Q1_2025[[#This Row],[Brutobedrag]]) -> 456 | P17: =IF(Q1_2025[[#This Row],[Prijstype]] = "Artikelprijs",Q1_2025[[#This Row],[Brutobedrag 2]]*(100-Q1_2025[[#This Row],[Relatiekorting percentage]])/100,Q1_2025[[#This Row],[Bruto - Rel.korting]]) -> 456
A18: AAO 2025.xls | B18: 5031053 | C18: Prolyte truss H30V 3 meter alu | D18: 33 | E18: 113.3 | F18: 3738.9 | G18: 2617.23 | H18: 30 | I18: =_xlfn.XLOOKUP(Q1_2025[[#This Row],[Artikelnr]],Artikel_prijzen[Artnr],Artikel_prijzen[Groep],"") | J18: =_xlfn.XLOOKUP(Q1_2025[[#This Row],[Artikelnr]],Artikel_prijzen[Artnr],Artikel_prijzen[Prijs 2025],"") | K18: =IF(Q1_2025[[#This Row],[Artikelprijs]]<>"",IF(Q1_2025[[#This Row],[Stuksprijs]]=Q1_2025[[#This Row],[Artikelprijs]],"Prijs gelijk","Prijs wijkt af"),"") | N18: =IF(Q1_2025[[#This Row],[Prijstype]]="Artikelprijs",Q1_2025[[#This Row],[Artikelprijs]],Q1_2025[[#This Row],[Stuksprijs]]) -> 113.3 | O18: =IF(Q1_2025[[#This Row],[Prijstype]]="Artikelprijs",Q1_2025[[#This Row],[Artikelprijs]] * Q1_2025[[#This Row],[Besteld]],Q1_2025[[#This Row],[Brutobedrag]]) -> 3738.9 | P18: =IF(Q1_2025[[#This Row],[Prijstype]] = "Artikelprijs",Q1_2025[[#This Row],[Brutobedrag 2]]*(100-Q1_2025[[#This Row],[Relatiekorting percentage]])/100,Q1_2025[[#This Row],[Bruto - Rel.korting]]) -> 2617.23
A19: AAO 2025.xls | B19: 5031052 | C19: Prolyte truss H30V 2 meter alu | D19: 5 | E19: 88.07 | F19: 440.35 | G19: 308.24 | H19: 30 | I19: =_xlfn.XLOOKUP(Q1_2025[[#This Row],[Artikelnr]],Artikel_prijzen[Artnr],Artikel_prijzen[Groep],"") | J19: =_xlfn.XLOOKUP(Q1_2025[[#This Row],[Artikelnr]],Artikel_prijzen[Artnr],Artikel_prijzen[Prijs 2025],"") | K19: =IF(Q1_2025[[#This Row],[Artikelprijs]]<>"",IF(Q1_2025[[#This Row],[Stuksprijs]]=Q1_2025[[#This Row],[Artikelprijs]],"Prijs gelijk","Prijs wijkt af"),"") | N19: =IF(Q1_2025[[#This Row],[Prijstype]]="Artikelprijs",Q1_2025[[#This Row],[Artikelprijs]],Q1_2025[[#This Row],[Stuksprijs]]) -> 88.07 | O19: =IF(Q1_2025[[#This Row],[Prijstype]]="Artikelprijs",Q1_2025[[#This Row],[Artikelprijs]] * Q1_2025[[#This Row],[Besteld]],Q1_2025[[#This Row],[Brutobedrag]]) -> 440.35 | P19: =IF(Q1_2025[[#This Row],[Prijstype]] = "Artikelprijs",Q1_2025[[#This Row],[Brutobedrag 2]]*(100-Q1_2025[[#This Row],[Relatiekorting percentage]])/100,Q1_2025[[#This Row],[Bruto - Rel.korting]]) -> 308.24
A20: AAO 2025.xls | B20: 5031051 | C20: Prolyte truss H30V 1 meter alu | D20: 2 | E20: 52.79 | F20: 105.58 | G20: 73.91 | H20: 30 | I20: =_xlfn.XLOOKUP(Q1_2025[[#This Row],[Artikelnr]],Artikel_prijzen[Artnr],Artikel_prijzen[Groep],"") | J20: =_xlfn.XLOOKUP(Q1_2025[[#This Row],[Artikelnr]],Artikel_prijzen[Artnr],Artikel_prijzen[Prijs 2025],"") | K20: =IF(Q1_2025[[#This Row],[Artikelprijs]]<>"",IF(Q1_2025[[#This Row],[Stuksprijs]]=Q1_2025[[#This Row],[Artikelprijs]],"Prijs gelijk","Prijs wijkt af"),"") | N20: =IF(Q1_2025[[#This Row],[Prijstype]]="Artikelprijs",Q1_2025[[#This Row],[Artikelprijs]],Q1_2025[[#This Row],[Stuksprijs]]) -> 52.79 | O20: =IF(Q1_2025[[#This Row],[Prijstype]]="Artikelprijs",Q1_2025[[#This Row],[Artikelprijs]] * Q1_2025[[#This Row],[Besteld]],Q1_2025[[#This Row],[Brutobedrag]]) -> 105.58 | P20: =IF(Q1_2025[[#This Row],[Prijstype]] = "Artikelprijs",Q1_2025[[#This Row],[Brutobedrag 2]]*(100-Q1_2025[[#This Row],[Relatiekorting percentage]])/100,Q1_2025[[#This Row],[Bruto - Rel.korting]]) -> 73.91
A21: AAO 2025.xls | B21: 5031049 | C21: Prolyte truss H30V 0,5 meter alu | D21: 1 | E21: 35.02 | F21: 35.02 | G21: 24.51 | H21: 30 | I21: =_xlfn.XLOOKUP(Q1_2025[[#This Row],[Artikelnr]],Artikel_prijzen[Artnr],Artikel_prijzen[Groep],"") | J21: =_xlfn.XLOOKUP(Q1_2025[[#This Row],[Artikelnr]],Artikel_prijzen[Artnr],Artikel_prijzen[Prijs 2025],"") | K21: =IF(Q1_2025[[#This Row],[Artikelprijs]]<>"",IF(Q1_2025[[#This Row],[Stuksprijs]]=Q1_2025[[#This Row],[Artikelprijs]],"Prijs gelijk","Prijs wijkt af"),"") | N21: =IF(Q1_2025[[#This Row],[Prijstype]]="Artikelprijs",Q1_2025[[#This Row],[Artikelprijs]],Q1_2025[[#This Row],[Stuksprijs]]) -> 35.02 | O21: =IF(Q1_2025[[#This Row],[Prijstype]]="Artikelprijs",Q1_2025[[#This Row],[Artikelprijs]] * Q1_2025[[#This Row],[Besteld]],Q1_2025[[#This Row],[Brutobedrag]]) -> 35.02 | P21: =IF(Q1_2025[[#This Row],[Prijstype]] = "Artikelprijs",Q1_2025[[#This Row],[Brutobedrag 2]]*(100-Q1_2025[[#This Row],[Relatiekorting percentage]])/100,Q1_2025[[#This Row],[Bruto - Rel.korting]]) -> 24.51
A22: AAO 2025.xls | B22: 5031047 | C22: Prolyte truss H30V 0,29 meter alu | D22: 1 | E22: 35.02 | F22: 35.02 | G22: 24.51 | H22: 30 | I22: =_xlfn.XLOOKUP(Q1_2025[[#This Row],[Artikelnr]],Artikel_prijzen[Artnr],Artikel_prijzen[Groep],"") | J22: =_xlfn.XLOOKUP(Q1_2025[[#This Row],[Artikelnr]],Artikel_prijzen[Artnr],Artikel_prijzen[Prijs 2025],"") | K22: =IF(Q1_2025[[#This Row],[Artikelprijs]]<>"",IF(Q1_2025[[#This Row],[Stuksprijs]]=Q1_2025[[#This Row],[Artikelprijs]],"Prijs gelijk","Prijs wijkt af"),"") | N22: =IF(Q1_2025[[#This Row],[Prijstype]]="Artikelprijs",Q1_2025[[#This Row],[Artikelprijs]],Q1_2025[[#This Row],[Stuksprijs]]) -> 35.02 | O22: =IF(Q1_2025[[#This Row],[Prijstype]]="Artikelprijs",Q1_2025[[#This Row],[Artikelprijs]] * Q1_2025[[#This Row],[Besteld]],Q1_2025[[#This Row],[Brutobedrag]]) -> 35.02 | P22: =IF(Q1_2025[[#This Row],[Prijstype]] = "Artikelprijs",Q1_2025[[#This Row],[Brutobedrag 2]]*(100-Q1_2025[[#This Row],[Relatiekorting percentage]])/100,Q1_2025[[#This Row],[Bruto - Rel.korting]]) -> 24.51
A23: AAO 2025.xls | B23: 5031056 | C23: Prolyte truss H30V Hoek V003 alu | D23: 4 | E23: 69.78 | F23: 279.12 | G23: 195.38 | H23: 30 | I23: =_xlfn.XLOOKUP(Q1_2025[[#This Row],[Artikelnr]],Artikel_prijzen[Artnr],Artikel_prijzen[Groep],"") | J23: =_xlfn.XLOOKUP(Q1_2025[[#This Row],[Artikelnr]],Artikel_prijzen[Artnr],Artikel_prijzen[Prijs 2025],"") | K23: =IF(Q1_2025[[#This Row],[Artikelprijs]]<>"",IF(Q1_2025[[#This Row],[Stuksprijs]]=Q1_2025[[#This Row],[Artikelprijs]],"Prijs gelijk","Prijs wijkt af"),"") | N23: =IF(Q1_2025[[#This Row],[Prijstype]]="Artikelprijs",Q1_2025[[#This Row],[Artikelprijs]],Q1_2025[[#This Row],[Stuksprijs]]) -> 69.78 | O23: =IF(Q1_2025[[#This Row],[Prijstype]]="Artikelprijs",Q1_2025[[#This Row],[Artikelprijs]] * Q1_2025[[#This Row],[Besteld]],Q1_2025[[#This Row],[Brutobedrag]]) -> 279.12 | P23: =IF(Q1_2025[[#This Row],[Prijstype]] = "Artikelprijs",Q1_2025[[#This Row],[Brutobedrag 2]]*(100-Q1_2025[[#This Row],[Relatiekorting percentage]])/100,Q1_2025[[#This Row],[Bruto - Rel.korting]]) -> 195.38
A24: AAO 2025.xls | B24: 5031059 | C24: Prolyte truss H30V Hoek V017 alu | D24: 1 | E24: 69.78 | F24: 69.78 | G24: 48.85 | H24: 30 | I24: =_xlfn.XLOOKUP(Q1_2025[[#This Row],[Artikelnr]],Artikel_prijzen[Artnr],Artikel_prijzen[Groep],"") | J24: =_xlfn.XLOOKUP(Q1_2025[[#This Row],[Artikelnr]],Artikel_prijzen[Artnr],Artikel_prijzen[Prijs 2025],"") | K24: =IF(Q1_2025[[#This Row],[Artikelprijs]]<>"",IF(Q1_2025[[#This Row],[Stuksprijs]]=Q1_2025[[#This Row],[Artikelprijs]],"Prijs gelijk","Prijs wijkt af"),"") | N24: =IF(Q1_2025[[#This Row],[Prijstype]]="Artikelprijs",Q1_2025[[#This Row],[Artikelprijs]],Q1_2025[[#This Row],[Stuksprijs]]) -> 69.78 | O24: =IF(Q1_2025[[#This Row],[Prijstype]]="Artikelprijs",Q1_2025[[#This Row],[Artikelprijs]] * Q1_2025[[#This Row],[Besteld]],Q1_2025[[#This Row],[Brutobedrag]]) -> 69.78 | P24: =IF(Q1_2025[[#This Row],[Prijstype]] = "Artikelprijs",Q1_2025[[#This Row],[Brutobedrag 2]]*(100-Q1_2025[[#This Row],[Relatiekorting percentage]])/100,Q1_2025[[#This Row],[Bruto - Rel.korting]]) -> 48.85
A25: AAO 2025.xls | B25: 5030229 | C25: Motortakel incl. ophangpunt + montage max 250kg | D25: 13 | E25: 303.85 | F25: 3950.05 | G25: 2765.03 | H25: 30 | I25: =_xlfn.XLOOKUP(Q1_2025[[#This Row],[Artikelnr]],Artikel_prijzen[Artnr],Artikel_prijzen[Groep],"") -> Rigging | J25: =_xlfn.XLOOKUP(Q1_2025[[#This Row],[Artikelnr]],Artikel_prijzen[Artnr],Artikel_prijzen[Prijs 2025],"") -> 295 | K25: =IF(Q1_2025[[#This Row],[Artikelprijs]]<>"",IF(Q1_2025[[#This Row],[Stuksprijs]]=Q1_2025[[#This Row],[Artikelprijs]],"Prijs gelijk","Prijs wijkt af"),"") -> Prijs wijkt af | M25: Artikelprijs | N25: =IF(Q1_2025[[#This Row],[Prijstype]]="Artikelprijs",Q1_2025[[#This Row],[Artikelprijs]],Q1_2025[[#This Row],[Stuksprijs]]) -> 295 | O25: =IF(Q1_2025[[#This Row],[Prijstype]]="Artikelprijs",Q1_2025[[#This Row],[Artikelprijs]] * Q1_2025[[#This Row],[Besteld]],Q1_2025[[#This Row],[Brutobedrag]]) -> 3835 | P25: =IF(Q1_2025[[#This Row],[Prijstype]] = "Artikelprijs",Q1_2025[[#This Row],[Brutobedrag 2]]*(100-Q1_2025[[#This Row],[Relatiekorting percentage]])/100,Q1_2025[[#This Row],[Bruto - Rel.korting]]) -> 2684.5
A26: AAO 2025.xls | B26: 3098001 | C26: Floodlight HQI - 2000W Asym. | D26: 20 | E26: 285 | F26: 5700 | G26: 4275 | H26: 25 | I26: =_xlfn.XLOOKUP(Q1_2025[[#This Row],[Artikelnr]],Artikel_prijzen[Artnr],Artikel_prijzen[Groep],"") | J26: =_xlfn.XLOOKUP(Q1_2025[[#This Row],[Artikelnr]],Artikel_prijzen[Artnr],Artikel_prijzen[Prijs 2025],"") | K26: =IF(Q1_2025[[#This Row],[Artikelprijs]]<>"",IF(Q1_2025[[#This Row],[Stuksprijs]]=Q1_2025[[#This Row],[Artikelprijs]],"Prijs gelijk","Prijs wijkt af"),"") | N26: =IF(Q1_2025[[#This Row],[Prijstype]]="Artikelprijs",Q1_2025[[#This Row],[Artikelprijs]],Q1_2025[[#This Row],[Stuksprijs]]) -> 285 | O26: =IF(Q1_2025[[#This Row],[Prijstype]]="Artikelprijs",Q1_2025[[#This Row],[Artikelprijs]] * Q1_2025[[#This Row],[Besteld]],Q1_2025[[#This Row],[Brutobedrag]]) -> 5700 | P26: =IF(Q1_2025[[#This Row],[Prijstype]] = "Artikelprijs",Q1_2025[[#This Row],[Brutobedrag 2]]*(100-Q1_2025[[#This Row],[Relatiekorting percentage]])/100,Q1_2025[[#This Row],[Bruto - Rel.korting]]) -> 4275
A27: AAO 2025.xls | B27: 5031053 | C27: Prolyte truss H30V 3 meter alu | D27: 49 | E27: 113.3 | F27: 5551.7 | G27: 3886.19 | H27: 30 | I27: =_xlfn.XLOOKUP(Q1_2025[[#This Row],[Artikelnr]],Artikel_prijzen[Artnr],Artikel_prijzen[Groep],"") | J27: =_xlfn.XLOOKUP(Q1_2025[[#This Row],[Artikelnr]],Artikel_prijzen[Artnr],Artikel_prijzen[Prijs 2025],"") | K27: =IF(Q1_2025[[#This Row],[Artikelprijs]]<>"",IF(Q1_2025[[#This Row],[Stuksprijs]]=Q1_2025[[#This Row],[Artikelprijs]],"Prijs gelijk","Prijs wijkt af"),"") | N27: =IF(Q1_2025[[#This Row],[Prijstype]]="Artikelprijs",Q1_2025[[#This Row],[Artikelprijs]],Q1_2025[[#This Row],[Stuksprijs]]) -> 113.3 | O27: =IF(Q1_2025[[#This Row],[Prijstype]]="Artikelprijs",Q1_2025[[#This Row],[Artikelprijs]] * Q1_2025[[#This Row],[Besteld]],Q1_2025[[#This Row],[Brutobedrag]]) -> 5551.7 | P27: =IF(Q1_2025[[#This Row],[Prijstype]] = "Artikelprijs",Q1_2025[[#This Row],[Brutobedrag 2]]*(100-Q1_2025[[#This Row],[Relatiekorting percentage]])/100,Q1_2025[[#This Row],[Bruto - Rel.korting]]) -> 3886.19
A28: AAO 2025.xls | B28: 5031052 | C28: Prolyte truss H30V 2 meter alu | D28: 2 | E28: 88.07 | F28: 176.14 | G28: 123.3 | H28: 30 | I28: =_xlfn.XLOOKUP(Q1_2025[[#This Row],[Artikelnr]],Artikel_prijzen[Artnr],Artikel_prijzen[Groep],"") | J28: =_xlfn.XLOOKUP(Q1_2025[[#This Row],[Artikelnr]],Artikel_prijzen[Artnr],Artikel_prijzen[Prijs 2025],"") | K28: =IF(Q1_2025[[#This Row],[Artikelprijs]]<>"",IF(Q1_2025[[#This Row],[Stuksprijs]]=Q1_2025[[#This Row],[Artikelprijs]],"Prijs gelijk","Prijs wijkt af"),"") | N28: =IF(Q1_2025[[#This Row],[Prijstype]]="Artikelprijs",Q1_2025[[#This Row],[Artikelprijs]],Q1_2025[[#This Row],[Stuksprijs]]) -> 88.07 | O28: =IF(Q1_2025[[#This Row],[Prijstype]]="Artikelprijs",Q1_2025[[#This Row],[Artikelprijs]] * Q1_2025[[#This Row],[Besteld]],Q1_2025[[#This Row],[Brutobedrag]]) -> 176.14 | P28: =IF(Q1_2025[[#This Row],[Prijstype]] = "Artikelprijs",Q1_2025[[#This Row],[Brutobedrag 2]]*(100-Q1_2025[[#This Row],[Relatiekorting percentage]])/100,Q1_2025[[#This Row],[Bruto - Rel.korting]]) -> 123.3
A29: AAO 2025.xls | B29: 2002096 | C29: Prolyte truss H30V 1 meter | D29: 2 | E29: 29.75 | F29: 59.5 | G29: 41.65 | H29: 30 | I29: =_xlfn.XLOOKUP(Q1_2025[[#This Row],[Artikelnr]],Artikel_prijzen[Artnr],Artikel_prijzen[Groep],"") | J29: =_xlfn.XLOOKUP(Q1_2025[[#This Row],[Artikelnr]],Artikel_prijzen[Artnr],Artikel_prijzen[Prijs 2025],"") | K29: =IF(Q1_2025[[#This Row],[Artikelprijs]]<>"",IF(Q1_2025[[#This Row],[Stuksprijs]]=Q1_2025[[#This Row],[Artikelprijs]],"Prijs gelijk","Prijs wijkt af"),"") | N29: =IF(Q1_2025[[#This Row],[Prijstype]]="Artikelprijs",Q1_2025[[#This Row],[Artikelprijs]],Q1_2025[[#This Row],[Stuksprijs]]) -> 29.75 | O29: =IF(Q1_2025[[#This Row],[Prijstype]]="Artikelprijs",Q1_2025[[#This Row],[Artikelprijs]] * Q1_2025[[#This Row],[Besteld]],Q1_2025[[#This Row],[Brutobedrag]]) -> 59.5 | P29: =IF(Q1_2025[[#This Row],[Prijstype]] = "Artikelprijs",Q1_2025[[#This Row],[Brutobedrag 2]]*(100-Q1_2025[[#This Row],[Relatiekorting percentage]])/100,Q1_2025[[#This Row],[Bruto - Rel.korting]]) -> 41.65
A30: AAO 2025.xls | B30: 5031047 | C30: Prolyte truss H30V 0,29 meter alu | D30: 3 | E30: 35.02 | F30: 105.06 | G30: 73.54 | H30: 30 | I30: =_xlfn.XLOOKUP(Q1_2025[[#This Row],[Artikelnr]],Artikel_prijzen[Artnr],Artikel_prijzen[Groep],"") | J30: =_xlfn.XLOOKUP(Q1_2025[[#This Row],[Artikelnr]],Artikel_prijzen[Artnr],Artikel_prijzen[Prijs 2025],"") | K30: =IF(Q1_2025[[#This Row],[Artikelprijs]]<>"",IF(Q1_2025[[#This Row],[Stuksprijs]]=Q1_2025[[#This Row],[Artikelprijs]],"Prijs gelijk","Prijs wijkt af"),"") | N30: =IF(Q1_2025[[#This Row],[Prijstype]]="Artikelprijs",Q1_2025[[#This Row],[Artikelprijs]],Q1_2025[[#This Row],[Stuksprijs]]) -> 35.02 | O30: =IF(Q1_2025[[#This Row],[Prijstype]]="Artikelprijs",Q1_2025[[#This Row],[Artikelprijs]] * Q1_2025[[#This Row],[Besteld]],Q1_2025[[#This Row],[Brutobedrag]]) -> 105.06 | P30: =IF(Q1_2025[[#This Row],[Prijstype]] = "Artikelprijs",Q1_2025[[#This Row],[Brutobedrag 2]]*(100-Q1_2025[[#This Row],[Relatiekorting percentage]])/100,Q1_2025[[#This Row],[Bruto - Rel.korting]]) -> 73.54
A31: AAO 2025.xls | B31: 5031056 | C31: Prolyte truss H30V Hoek V003 alu | D31: 2 | E31: 69.78 | F31: 139.56 | G31: 97.69 | H31: 30 | I31: =_xlfn.XLOOKUP(Q1_2025[[#This Row],[Artikelnr]],Artikel_prijzen[Artnr],Artikel_prijzen[Groep],"") | J31: =_xlfn.XLOOKUP(Q1_2025[[#This Row],[Artikelnr]],Artikel_prijzen[Artnr],Artikel_prijzen[Prijs 2025],"") | K31: =IF(Q1_2025[[#This Row],[Artikelprijs]]<>"",IF(Q1_2025[[#This Row],[Stuksprijs]]=Q1_2025[[#This Row],[Artikelprijs]],"Prijs gelijk","Prijs wijkt af"),"") | N31: =IF(Q1_2025[[#This Row],[Prijstype]]="Artikelprijs",Q1_2025[[#This Row],[Artikelprijs]],Q1_2025[[#This Row],[Stuksprijs]]) -> 69.78 | O31: =IF(Q1_2025[[#This Row],[Prijstype]]="Artikelprijs",Q1_2025[[#This Row],[Artikelprijs]] * Q1_2025[[#This Row],[Besteld]],Q1_2025[[#This Row],[Brutobedrag]]) -> 139.56 | P31: =IF(Q1_2025[[#This Row],[Prijstype]] = "Artikelprijs",Q1_2025[[#This Row],[Brutobedrag 2]]*(100-Q1_2025[[#This Row],[Relatiekorting percentage]])/100,Q1_2025[[#This Row],[Bruto - Rel.korting]]) -> 97.69
A32: AAO 2025.xls | B32: 5031072 | C32: Prolyte truss H30V Hoek V005 alu | D32: 4 | E32: 69.78 | F32: 279.12 | G32: 195.38 | H32: 30 | I32: =_xlfn.XLOOKUP(Q1_2025[[#This Row],[Artikelnr]],Artikel_prijzen[Artnr],Artikel_prijzen[Groep],"") | J32: =_xlfn.XLOOKUP(Q1_2025[[#This Row],[Artikelnr]],Artikel_prijzen[Artnr],Artikel_prijzen[Prijs 2025],"") | K32: =IF(Q1_2025[[#This Row],[Artikelprijs]]<>"",IF(Q1_2025[[#This Row],[Stuksprijs]]=Q1_2025[[#This Row],[Artikelprijs]],"Prijs gelijk","Prijs wijkt af"),"") | N32: =IF(Q1_2025[[#This Row],[Prijstype]]="Artikelprijs",Q1_2025[[#This Row],[Artikelprijs]],Q1_2025[[#This Row],[Stuksprijs]]) -> 69.78 | O32: =IF(Q1_2025[[#This Row],[Prijstype]]="Artikelprijs",Q1_2025[[#This Row],[Artikelprijs]] * Q1_2025[[#This Row],[Besteld]],Q1_2025[[#This Row],[Brutobedrag]]) -> 279.12 | P32: =IF(Q1_2025[[#This Row],[Prijstype]] = "Artikelprijs",Q1_2025[[#This Row],[Brutobedrag 2]]*(100-Q1_2025[[#This Row],[Relatiekorting percentage]])/100,Q1_2025[[#This Row],[Bruto - Rel.korting]]) -> 195.38
A33: AAO 2025.xls | B33: 2001027 | C33: Prolyte truss Spacer 3 cm | D33: 4 | E33: 8.65 | F33: 0 | G33: 0 | H33: 30 | I33: =_xlfn.XLOOKUP(Q1_2025[[#This Row],[Artikelnr]],Artikel_prijzen[Artnr],Artikel_prijzen[Groep],"") | J33: =_xlfn.XLOOKUP(Q1_2025[[#This Row],[Artikelnr]],Artikel_prijzen[Artnr],Artikel_prijzen[Prijs 2025],"") | K33: =IF(Q1_2025[[#This Row],[Artikelprijs]]<>"",IF(Q1_2025[[#This Row],[Stuksprijs]]=Q1_2025[[#This Row],[Artikelprijs]],"Prijs gelijk","Prijs wijkt af"),"") | N33: =IF(Q1_2025[[#This Row],[Prijstype]]="Artikelprijs",Q1_2025[[#This Row],[Artikelprijs]],Q1_2025[[#This Row],[Stuksprijs]]) -> 8.65 | O33: =IF(Q1_2025[[#This Row],[Prijstype]]="Artikelprijs",Q1_2025[[#This Row],[Artikelprijs]] * Q1_2025[[#This Row],[Besteld]],Q1_2025[[#This Row],[Brutobedrag]]) -> 0 | P33: =IF(Q1_2025[[#This Row],[Prijstype]] = "Artikelprijs",Q1_2025[[#This Row],[Brutobedrag 2]]*(100-Q1_2025[[#This Row],[Relatiekorting percentage]])/100,Q1_2025[[#This Row],[Bruto - Rel.korting]]) -> 0
A34: AAO 2025.xls | B34: 5030229 | C34: Motortakel incl. ophangpunt + montage max 250kg | D34: 18 | E34: 303.85 | F34: 5469.3 | G34: 3828.51 | H34: 30 | I34: =_xlfn.XLOOKUP(Q1_2025[[#This Row],[Artikelnr]],Artikel_prijzen[Artnr],Artikel_prijzen[Groep],"") -> Rigging | J34: =_xlfn.XLOOKUP(Q1_2025[[#This Row],[Artikelnr]],Artikel_prijzen[Artnr],Artikel_prijzen[Prijs 2025],"") -> 295 | K34: =IF(Q1_2025[[#This Row],[Artikelprijs]]<>"",IF(Q1_2025[[#This Row],[Stuksprijs]]=Q1_2025[[#This Row],[Artikelprijs]],"Prijs gelijk","Prijs wijkt af"),"") -> Prijs wijkt af | M34: Artikelprijs | N34: =IF(Q1_2025[[#This Row],[Prijstype]]="Artikelprijs",Q1_2025[[#This Row],[Artikelprijs]],Q1_2025[[#This Row],[Stuksprijs]]) -> 295 | O34: =IF(Q1_2025[[#This Row],[Prijstype]]="Artikelprijs",Q1_2025[[#This Row],[Artikelprijs]] * Q1_2025[[#This Row],[Besteld]],Q1_2025[[#This Row],[Brutobedrag]]) -> 5310 | P34: =IF(Q1_2025[[#This Row],[Prijstype]] = "Artikelprijs",Q1_2025[[#This Row],[Brutobedrag 2]]*(100-Q1_2025[[#This Row],[Relatiekorting percentage]])/100,Q1_2025[[#This Row],[Bruto - Rel.korting]]) -> 3717
A35: AAO 2025.xls | B35: 3098001 | C35: Luxibel wash BP9Z | D35: 24 | E35: 225 | F35: 5400 | G35: 4050 | H35: 25 | I35: =_xlfn.XLOOKUP(Q1_2025[[#This Row],[Artikelnr]],Artikel_prijzen[Artnr],Artikel_prijzen[Groep],"") | J35: =_xlfn.XLOOKUP(Q1_2025[[#This Row],[Artikelnr]],Artikel_prijzen[Artnr],Artikel_prijzen[Prijs 2025],"") | K35: =IF(Q1_2025[[#This Row],[Artikelprijs]]<>"",IF(Q1_2025[[#This Row],[Stuksprijs]]=Q1_2025[[#This Row],[Artikelprijs]],"Prijs gelijk","Prijs wijkt af"),"") | N35: =IF(Q1_2025[[#This Row],[Prijstype]]="Artikelprijs",Q1_2025[[#This Row],[Artikelprijs]],Q1_2025[[#This Row],[Stuksprijs]]) -> 225 | O35: =IF(Q1_2025[[#This Row],[Prijstype]]="Artikelprijs",Q1_2025[[#This Row],[Artikelprijs]] * Q1_2025[[#This Row],[Besteld]],Q1_2025[[#This Row],[Brutobedrag]]) -> 5400 | P35: =IF(Q1_2025[[#This Row],[Prijstype]] = "Artikelprijs",Q1_2025[[#This Row],[Brutobedrag 2]]*(100-Q1_2025[[#This Row],[Relatiekorting percentage]])/100,Q1_2025[[#This Row],[Bruto - Rel.korting]]) -> 4050
A36: AAO 2025.xls | B36: 3098001 | C36: LED Moving Head Clay Paky Sharpy X-Frame | D36: 12 | E36: 605 | F36: 7260 | G36: 5445 | H36: 25 | I36: =_xlfn.XLOOKUP(Q1_2025[[#This Row],[Artikelnr]],Artikel_prijzen[Artnr],Artikel_prijzen[Groep],"") | J36: =_xlfn.XLOOKUP(Q1_2025[[#This Row],[Artikelnr]],Artikel_prijzen[Artnr],Artikel_prijzen[Prijs 2025],"") | K36: =IF(Q1_2025[[#This Row],[Artikelprijs]]<>"",IF(Q1_2025[[#This Row],[Stuksprijs]]=Q1_2025[[#This Row],[Artikelprijs]],"Prijs gelijk","Prijs wijkt af"),"") | N36: =IF(Q1_2025[[#This Row],[Prijstype]]="Artikelprijs",Q1_2025[[#This Row],[Artikelprijs]],Q1_2025[[#This Row],[Stuksprijs]]) -> 605 | O36: =IF(Q1_2025[[#This Row],[Prijstype]]="Artikelprijs",Q1_2025[[#This Row],[Artikelprijs]] * Q1_2025[[#This Row],[Besteld]],Q1_2025[[#This Row],[Brutobedrag]]) -> 7260 | P36: =IF(Q1_2025[[#This Row],[Prijstype]] = "Artikelprijs",Q1_2025[[#This Row],[Brutobedrag 2]]*(100-Q1_2025[[#This Row],[Relatiekorting percentage]])/100,Q1_2025[[#This Row],[Bruto - Rel.korting]]) -> 5445
A37: AAO 2025.xls | B37: 5010001 | C37: Grand MA3 Licht regeltafel | D37: 1 | E37: 1450 | F37: 1450 | G37: 1087.5 | H37: 25 | I37: =_xlfn.XLOOKUP(Q1_2025[[#This Row],[Artikelnr]],Artikel_prijzen[Artnr],Artikel_prijzen[Groep],"") | J37: =_xlfn.XLOOKUP(Q1_2025[[#This Row],[Artikelnr]],Artikel_prijzen[Artnr],Artikel_prijzen[Prijs 2025],"") | K37: =IF(Q1_2025[[#This Row],[Artikelprijs]]<>"",IF(Q1_2025[[#This Row],[Stuksprijs]]=Q1_2025[[#This Row],[Artikelprijs]],"Prijs gelijk","Prijs wijkt af"),"") | N37: =IF(Q1_2025[[#This Row],[Prijstype]]="Artikelprijs",Q1_2025[[#This Row],[Artikelprijs]],Q1_2025[[#This Row],[Stuksprijs]]) -> 1450 | O37: =IF(Q1_2025[[#This Row],[Prijstype]]="Artikelprijs",Q1_2025[[#This Row],[Artikelprijs]] * Q1_2025[[#This Row],[Besteld]],Q1_2025[[#This Row],[Brutobedrag]]) -> 1450 | P37: =IF(Q1_2025[[#This Row],[Prijstype]] = "Artikelprijs",Q1_2025[[#This Row],[Brutobedrag 2]]*(100-Q1_2025[[#This Row],[Relatiekorting percentage]])/100,Q1_2025[[#This Row],[Bruto - Rel.korting]]) -> 1087.5
A38: AAO 2025.xls | B38: 5030229 | C38: Motortakel incl. ophangpunt + montage max 250kg | D38: 4 | E38: 303.85 | F38: 1215.4 | G38: 850.78 | H38: 30 | I38: =_xlfn.XLOOKUP(Q1_2025[[#This Row],[Artikelnr]],Artikel_prijzen[Artnr],Artikel_prijzen[Groep],"") -> Rigging | J38: =_xlfn.XLOOKUP(Q1_2025[[#This Row],[Artikelnr]],Artikel_prijzen[Artnr],Artikel_prijzen[Prijs 2025],"") -> 295 | K38: =IF(Q1_2025[[#This Row],[Artikelprijs]]<>"",IF(Q1_2025[[#This Row],[Stuksprijs]]=Q1_2025[[#This Row],[Artikelprijs]],"Prijs gelijk","Prijs wijkt af"),"") -> Prijs wijkt af | M38: Artikelprijs | N38: =IF(Q1_2025[[#This Row],[Prijstype]]="Artikelprijs",Q1_2025[[#This Row],[Artikelprijs]],Q1_2025[[#This Row],[Stuksprijs]]) -> 295 | O38: =IF(Q1_2025[[#This Row],[Prijstype]]="Artikelprijs",Q1_2025[[#This Row],[Artikelprijs]] * Q1_2025[[#This Row],[Besteld]],Q1_2025[[#This Row],[Brutobedrag]]) -> 1180 | P38: =IF(Q1_2025[[#This Row],[Prijstype]] = "Artikelprijs",Q1_2025[[#This Row],[Brutobedrag 2]]*(100-Q1_2025[[#This Row],[Relatiekorting percentage]])/100,Q1_2025[[#This Row],[Bruto - Rel.korting]]) -> 826
A39: AAO 2025.xls | B39: 5030229 | C39: Motortakel incl. ophangpunt + montage max 250kg | D39: 3 | E39: 303.85 | F39: 911.55 | G39: 638.08 | H39: 30 | I39: =_xlfn.XLOOKUP(Q1_2025[[#This Row],[Artikelnr]],Artikel_prijzen[Artnr],Artikel_prijzen[Groep],"") -> Rigging | J39: =_xlfn.XLOOKUP(Q1_2025[[#This Row],[Artikelnr]],Artikel_prijzen[Artnr],Artikel_prijzen[Prijs 2025],"") -> 295 | K39: =IF(Q1_2025[[#This Row],[Artikelprijs]]<>"",IF(Q1_2025[[#This Row],[Stuksprijs]]=Q1_2025[[#This Row],[Artikelprijs]],"Prijs gelijk","Prijs wijkt af"),"") -> Prijs wijkt af | M39: Artikelprijs | N39: =IF(Q1_2025[[#This Row],[Prijstype]]="Artikelprijs",Q1_2025[[#This Row],[Artikelprijs]],Q1_2025[[#This Row],[Stuksprijs]]) -> 295 | O39: =IF(Q1_2025[[#This Row],[Prijstype]]="Artikelprijs",Q1_2025[[#This Row],[Artikelprijs]] * Q1_2025[[#This Row],[Besteld]],Q1_2025[[#This Row],[Brutobedrag]]) -> 885 | P39: =IF(Q1_2025[[#This Row],[Prijstype]] = "Artikelprijs",Q1_2025[[#This Row],[Brutobedrag 2]]*(100-Q1_2025[[#This Row],[Relatiekorting percentage]])/100,Q1_2025[[#This Row],[Bruto - Rel.korting]]) -> 619.5
A40: AAO 2025.xls | B40: 5031051 | C40: Prolyte truss H30V 1 meter alu | D40: 1 | E40: 52.79 | F40: 52.79 | G40: 36.95 | H40: 30 | I40: =_xlfn.XLOOKUP(Q1_2025[[#This Row],[Artikelnr]],Artikel_prijzen[Artnr],Artikel_prijzen[Groep],"") | J40: =_xlfn.XLOOKUP(Q1_2025[[#This Row],[Artikelnr]],Artikel_prijzen[Artnr],Artikel_prijzen[Prijs 2025],"") | K40: =IF(Q1_2025[[#This Row],[Artikelprijs]]<>"",IF(Q1_2025[[#This Row],[Stuksprijs]]=Q1_2025[[#This Row],[Artikelprijs]],"Prijs gelijk","Prijs wijkt af"),"") | N40: =IF(Q1_2025[[#This Row],[Prijstype]]="Artikelprijs",Q1_2025[[#This Row],[Artikelprijs]],Q1_2025[[#This Row],[Stuksprijs]]) -> 52.79 | O40: =IF(Q1_2025[[#This Row],[Prijstype]]="Artikelprijs",Q1_2025[[#This Row],[Artikelprijs]] * Q1_2025[[#This Row],[Besteld]],Q1_2025[[#This Row],[Brutobedrag]]) -> 52.79 | P40: =IF(Q1_2025[[#This Row],[Prijstype]] = "Artikelprijs",Q1_2025[[#This Row],[Brutobedrag 2]]*(100-Q1_2025[[#This Row],[Relatiekorting percentage]])/100,Q1_2025[[#This Row],[Bruto - Rel.korting]]) -> 36.95
...

Sheet Q1 Provisie
B1: Provisie berekening Q1 2025
B4: Provisie | C4: Percentage | D4: Omzet | E4: Provisie
B5: Elektra | C5: 0.23 | D5: =C34 -> 352164.59 | E5: =C5*D5 -> 80997.857
B6: Rigging | C6: 0.16 | D6: =D34 -> 284656.04 | E6: =C6*D6 -> 45544.966
B7: AV | C7: 0.15 | D7: =E34 -> 33369.99 | E7: =C7*D7 -> 5005.4985
B8: Omzet Q1 | C8: 0.05 | D8: =G34 -> 1139176.7 | E8: =D8*C8 -> 56958.835
B9: Omzet voor het jaar | D9: =D8 -> 1139176.7
B10: Omzetstaffels 6,5% en 8% worden in Q4 verrekend
B11: TOTALE PROVISIE | E11: =SUM(E5:E10) -> 188507.16
B14: Evenementen Q1 2025 | C14: Elektra omzet | D14: Rigging omzet | E14: AV omzet | F14: Geen groep omzet | G14: Totaal Omzet | H14: Elektra provisie | I14: Rigging provisie | J14: AV Provisie
B15: {=_xlfn.UNIQUE(Q1_2025[Evenement])} -> 4AM Festival.xls | C15: =SUMIFS(Q1_2025[Bruto-Rel. korting 2],Q1_2025[Evenement],B15,Q1_2025[Groep],$B$5) -> 417.15 | D15: =SUMIFS(Q1_2025[Bruto-Rel. korting 2],Q1_2025[Evenement],B15,Q1_2025[Groep],$B$6) -> 0 | E15: =SUMIFS(Q1_2025[Bruto-Rel. korting 2],Q1_2025[Evenement],B15,Q1_2025[Groep],$B$7) -> 0 | F15: =SUMIFS(Q1_2025[Bruto-Rel. korting 2],Q1_2025[Evenement],B15,Q1_2025[Groep],"") -> 0 | G15: =SUM(C15:F15) -> 417.15 | H15: =C15*$C$5 -> 95.9445 | I15: =D15*$C$6 -> 0 | J15: =E15*$C$7 -> 0
B16: AAO 2025.xls | C16: =SUMIFS(Q1_2025[Bruto-Rel. korting 2],Q1_2025[Evenement],B16,Q1_2025[Groep],$B$5) -> 51534.646 | D16: =SUMIFS(Q1_2025[Bruto-Rel. korting 2],Q1_2025[Evenement],B16,Q1_2025[Groep],$B$6) -> 82566.6 | E16: =SUMIFS(Q1_2025[Bruto-Rel. korting 2],Q1_2025[Evenement],B16,Q1_2025[Groep],$B$7) -> 0 | F16: =SUMIFS(Q1_2025[Bruto-Rel. korting 2],Q1_2025[Evenement],B16,Q1_2025[Groep],"") -> 242117.48 | G16: =SUM(C16:F16) -> 376218.73 | H16: =C16*$C$5 -> 11852.969 | I16: =D16*$C$6 -> 13210.656 | J16: =E16*$C$7 -> 0
B17: Art Rotterdam 2025.xls | C17: =SUMIFS(Q1_2025[Bruto-Rel. korting 2],Q1_2025[Evenement],B17,Q1_2025[Groep],$B$5) -> 29774.6 | D17: =SUMIFS(Q1_2025[Bruto-Rel. korting 2],Q1_2025[Evenement],B17,Q1_2025[Groep],$B$6) -> 29483.75 | E17: =SUMIFS(Q1_2025[Bruto-Rel. korting 2],Q1_2025[Evenement],B17,Q1_2025[Groep],$B$7) -> 0 | F17: =SUMIFS(Q1_2025[Bruto-Rel. korting 2],Q1_2025[Evenement],B17,Q1_2025[Groep],"") -> 45506.49 | G17: =SUM(C17:F17) -> 104764.84 | H17: =C17*$C$5 -> 6848.158 | I17: =D17*$C$6 -> 4717.4 | J17: =E17*$C$7 -> 0
B18: C2C Festival 2025.xls | C18: =SUMIFS(Q1_2025[Bruto-Rel. korting 2],Q1_2025[Evenement],B18,Q1_2025[Groep],$B$5) -> 2207.79 | D18: =SUMIFS(Q1_2025[Bruto-Rel. korting 2],Q1_2025[Evenement],B18,Q1_2025[Groep],$B$6) -> 0 | E18: =SUMIFS(Q1_2025[Bruto-Rel. korting 2],Q1_2025[Evenement],B18,Q1_2025[Groep],$B$7) -> 0 | F18: =SUMIFS(Q1_2025[Bruto-Rel. korting 2],Q1_2025[Evenement],B18,Q1_2025[Groep],"") -> 0 | G18: =SUM(C18:F18) -> 2207.79 | H18: =C18*$C$5 -> 507.7917 | I18: =D18*$C$6 -> 0 | J18: =E18*$C$7 -> 0
B19: Comic Film & Manga Fest 2025.xls | C19: =SUMIFS(Q1_2025[Bruto-Rel. korting 2],Q1_2025[Evenement],B19,Q1_2025[Groep],$B$5) -> 2412.775 | D19: =SUMIFS(Q1_2025[Bruto-Rel. korting 2],Q1_2025[Evenement],B19,Q1_2025[Groep],$B$6) -> 0 | E19: =SUMIFS(Q1_2025[Bruto-Rel. korting 2],Q1_2025[Evenement],B19,Q1_2025[Groep],$B$7) -> 0 | F19: =SUMIFS(Q1_2025[Bruto-Rel. korting 2],Q1_2025[Evenement],B19,Q1_2025[Groep],"") -> 0 | G19: =SUM(C19:F19) -> 2412.775 | H19: =C19*$C$5 -> 554.93825 | I19: =D19*$C$6 -> 0 | J19: =E19*$C$7 -> 0
B20: Holiday on Ice 2025.xls | C20: =SUMIFS(Q1_2025[Bruto-Rel. korting 2],Q1_2025[Evenement],B20,Q1_2025[Groep],$B$5) -> 5265.44 | D20: =SUMIFS(Q1_2025[Bruto-Rel. korting 2],Q1_2025[Evenement],B20,Q1_2025[Groep],$B$6) -> 0 | E20: =SUMIFS(Q1_2025[Bruto-Rel. korting 2],Q1_2025[Evenement],B20,Q1_2025[Groep],$B$7) -> 0 | F20: =SUMIFS(Q1_2025[Bruto-Rel. korting 2],Q1_2025[Evenement],B20,Q1_2025[Groep],"") -> 6481.26 | G20: =SUM(C20:F20) -> 11746.7 | H20: =C20*$C$5 -> 1211.0512 | I20: =D20*$C$6 -> 0 | J20: =E20*$C$7 -> 0
B21: Hyrox 2025.xls | C21: =SUMIFS(Q1_2025[Bruto-Rel. korting 2],Q1_2025[Evenement],B21,Q1_2025[Groep],$B$5) -> 12116 | D21: =SUMIFS(Q1_2025[Bruto-Rel. korting 2],Q1_2025[Evenement],B21,Q1_2025[Groep],$B$6) -> 0 | E21: =SUMIFS(Q1_2025[Bruto-Rel. korting 2],Q1_2025[Evenement],B21,Q1_2025[Groep],$B$7) -> 0 | F21: =SUMIFS(Q1_2025[Bruto-Rel. korting 2],Q1_2025[Evenement],B21,Q1_2025[Groep],"") -> 704.85 | G21: =SUM(C21:F21) -> 12820.85 | H21: =C21*$C$5 -> 2786.68 | I21: =D21*$C$6 -> 0 | J21: =E21*$C$7 -> 0
B22: Infratech 2025 - Elektra.xls | C22: =SUMIFS(Q1_2025[Bruto-Rel. korting 2],Q1_2025[Evenement],B22,Q1_2025[Groep],$B$5) -> 89237.79 | D22: =SUMIFS(Q1_2025[Bruto-Rel. korting 2],Q1_2025[Evenement],B22,Q1_2025[Groep],$B$6) -> 0 | E22: =SUMIFS(Q1_2025[Bruto-Rel. korting 2],Q1_2025[Evenement],B22,Q1_2025[Groep],$B$7) -> 18480 | F22: =SUMIFS(Q1_2025[Bruto-Rel. korting 2],Q1_2025[Evenement],B22,Q1_2025[Groep],"") -> 14861.99 | G22: =SUM(C22:F22) -> 122579.78 | H22: =C22*$C$5 -> 20524.692 | I22: =D22*$C$6 -> 0 | J22: =E22*$C$7 -> 2772
B23: Infratech 2025 - Rigging.xls | C23: =SUMIFS(Q1_2025[Bruto-Rel. korting 2],Q1_2025[Evenement],B23,Q1_2025[Groep],$B$5) -> 700 | D23: =SUMIFS(Q1_2025[Bruto-Rel. korting 2],Q1_2025[Evenement],B23,Q1_2025[Groep],$B$6) -> 106779.4 | E23: =SUMIFS(Q1_2025[Bruto-Rel. korting 2],Q1_2025[Evenement],B23,Q1_2025[Groep],$B$7) -> 0 | F23: =SUMIFS(Q1_2025[Bruto-Rel. korting 2],Q1_2025[Evenement],B23,Q1_2025[Groep],"") -> 3635.49 | G23: =SUM(C23:F23) -> 111114.89 | H23: =C23*$C$5 -> 161 | I23: =D23*$C$6 -> 17084.704 | J23: =E23*$C$7 -> 0
B24: Infratech 2025 - Stands.xls | C24: =SUMIFS(Q1_2025[Bruto-Rel. korting 2],Q1_2025[Evenement],B24,Q1_2025[Groep],$B$5) -> 12190.05 | D24: =SUMIFS(Q1_2025[Bruto-Rel. korting 2],Q1_2025[Evenement],B24,Q1_2025[Groep],$B$6) -> 21567 | E24: =SUMIFS(Q1_2025[Bruto-Rel. korting 2],Q1_2025[Evenement],B24,Q1_2025[Groep],$B$7) -> 8693 | F24: =SUMIFS(Q1_2025[Bruto-Rel. korting 2],Q1_2025[Evenement],B24,Q1_2025[Groep],"") -> 117399.71 | G24: =SUM(C24:F24) -> 159849.76 | H24: =C24*$C$5 -> 2803.7115 | I24: =D24*$C$6 -> 3450.72 | J24: =E24*$C$7 -> 1303.95
B25: Record & CD Fair 2025.xls | C25: =SUMIFS(Q1_2025[Bruto-Rel. korting 2],Q1_2025[Evenement],B25,Q1_2025[Groep],$B$5) -> 154.5 | D25: =SUMIFS(Q1_2025[Bruto-Rel. korting 2],Q1_2025[Evenement],B25,Q1_2025[Groep],$B$6) -> 0 | E25: =SUMIFS(Q1_2025[Bruto-Rel. korting 2],Q1_2025[Evenement],B25,Q1_2025[Groep],$B$7) -> 0 | F25: =SUMIFS(Q1_2025[Bruto-Rel. korting 2],Q1_2025[Evenement],B25,Q1_2025[Groep],"") -> 0 | G25: =SUM(C25:F25) -> 154.5 | H25: =C25*$C$5 -> 35.535 | I25: =D25*$C$6 -> 0 | J25: =E25*$C$7 -> 0
B26: Rotterdam Rave 2025.xls | C26: =SUMIFS(Q1_2025[Bruto-Rel. korting 2],Q1_2025[Evenement],B26,Q1_2025[Groep],$B$5) -> 4990.03 | D26: =SUMIFS(Q1_2025[Bruto-Rel. korting 2],Q1_2025[Evenement],B26,Q1_2025[Groep],$B$6) -> 0 | E26: =SUMIFS(Q1_2025[Bruto-Rel. korting 2],Q1_2025[Evenement],B26,Q1_2025[Groep],$B$7) -> 0 | F26: =SUMIFS(Q1_2025[Bruto-Rel. korting 2],Q1_2025[Evenement],B26,Q1_2025[Groep],"") -> 2607.52 | G26: =SUM(C26:F26) -> 7597.55 | H26: =C26*$C$5 -> 1147.7069 | I26: =D26*$C$6 -> 0 | J26: =E26*$C$7 -> 0
B27: Rotterdam Tattoo Convention 2025.xls | C27: =SUMIFS(Q1_2025[Bruto-Rel. korting 2],Q1_2025[Evenement],B27,Q1_2025[Groep],$B$5) -> 19611.56 | D27: =SUMIFS(Q1_2025[Bruto-Rel. korting 2],Q1_2025[Evenement],B27,Q1_2025[Groep],$B$6) -> 1215.4 | E27: =SUMIFS(Q1_2025[Bruto-Rel. korting 2],Q1_2025[Evenement],B27,Q1_2025[Groep],$B$7) -> 0 | F27: =SUMIFS(Q1_2025[Bruto-Rel. korting 2],Q1_2025[Evenement],B27,Q1_2025[Groep],"") -> 0 | G27: =SUM(C27:F27) -> 20826.96 | H27: =C27*$C$5 -> 4510.6588 | I27: =D27*$C$6 -> 194.464 | J27: =E27*$C$7 -> 0
... B33: VVAL 2025.xls | C33: =SUMIFS(Q1_2025[Bruto-Rel. korting 2],Q1_2025[Evenement],B33,Q1_2025[Groep],$B$5) -> 19826.212 | D33: =SUMIFS(Q1_2025[Bruto-Rel. korting 2],Q1_2025[Evenement],B33,Q1_2025[Groep],$B$6) -> 0 | E33: =SUMIFS(Q1_2025[Bruto-Rel. korting 2],Q1_2025[Evenement],B33,Q1_2025[Groep],$B$7) -> 0 | F33: =SUMIFS(Q1_2025[Bruto-Rel. korting 2],Q1_2025[Evenement],B33,Q1_2025[Groep],"") -> 20454.06 | G33: =SUM(C33:F33) -> 40280.272 | H33: =C33*$C$5 -> 4560.0289 | I33: =D33*$C$6 -> 0 | J33: =E33*$C$7 -> 0
B34: TOTAAL | C34: =SUM(C15:C33) -> 352164.59 | D34: =SUM(D15:D33) -> 284656.04 | E34: =SUM(E15:E33) -> 33369.99 | F34: =SUM(F15:F33) -> 473681.12 | G34: 1139176.7 | H34: =SUM(H15:H33) -> 80997.857 | I34: =SUM(I15:I33) -> 45544.966 | J34: =SUM(J15:J33) -> 5005.4985

Sheet Q1 PT
A3: Evenement | B3: Artikelnr | C3: Omschrijving | D3: Groep | E3: Som van Besteld
A4: 4AM Festival.xls | B4: 5021001 | C4: Stroomaansl. 3kW + WCD + Verbruik 1d | D4: Elektra | E4: 3
A5: AAO 2025.xls | B5: 1001013 | C5: Railspot Lumina LED 20w tri color zilver | E5: 20
B6: 1001021 | C6: Railspot Milano LED 30w 3000K zwart dimbaar | E6: 83
B7: 1001028 | C7: Railspot Lumina LED 20w tri color zilver | E7: 20
B8: 1001031 | C8: Railspot Lumina LED 30w 4000K zwart | E8: 6
B9: 1002019 | C9: Pendel LED Luxa 30 watt/ 3000K zilver | E9: 10
B10: 1002020 | C10: Pendel LED Luxa 30 watt/ 4000K zilver | E10: 10
B11: 1002032 | C11: Pendel LED Luxa 30 watt tri color zilver | E11: 22
B12: 1003011 | C12: Inbouwspot Lika LED 9W 4000K Ø 83mm wit | E12: 17
B13: 1003012 | C13: Inbouwspot Lika LED 9W 3000K Ø 83mm wit | E13: 3
B14: 1003030 | C14: Inbouwspot Vivaro LED 5W 4000K Ø 75mm wit | E14: 4
B15: 1005013 | C15: Hanglamp Kooldraad LED | E15: 50
B16: 1005015 | C16: Hanglamp enkelt vitting E27 zwart | E16: 10
B17: 1007023 | C17: Prikkabel 10m LED wit | E17: 2
... B28: 1098001 | C28: Blacklight armatuur | E28: 4
C29: Luxibel BPar180RGBW v2 | E29: 67
C30: Magneten tbv spanningsrail | E30: 50
B31: 1098002 | C31: Credit factuur | E31: 1
B32: 1099009 | C32: Spectral M800 LED 65 watt RGBW | E32: 1
B33: 2001027 | C33: Prolyte truss Spacer 3 cm | E33: 4
B34: 2001041 | C34: Prolyte truss X30D 0,29 meter zwart | E34: 2
B35: 2001045 | C35: Prolyte truss X30D 2 meter zwart | E35: 34
B36: 2001048 | C36: Prolyte truss X30D Hoek D003 zwart | E36: 4
B37: 2001088 | C37: Prolyte cirkeltruss X30D 8 meter zwart | E37: 1
B38: 2001089 | C38: Prolyte truss X30D 3 meter zwart | E38: 62
B39: 2001090 | C39: Prolyte truss X30D 3 meter zwart | E39: 34
B40: 2002005 | C40: Prolyte truss H30V 1 meter | E40: 1
B41: 2002006 | C41: Prolyte truss H30V 2 meter | E41: 9
B42: 2002007 | C42: Prolyte truss H30V 3 meter | E42: 14
... B77: 2098001 | C77: Gordijnen 3 x 6 mtr. | E77: 4
C78: Gordijnen 3 x 8 mtr. | E78: 25
C79: TRNH34-T(M) - (50x50 T-stuk) | E79: 4
B80: 3001025 | C80: Verlengkabel shuko 3x2.5mm² 10 meter | E80: 11
B81: 3001031 | C81: Verloop 32A/63A | E81: 4
B82: 3001035 | C82: Wieland verlengkabel 1 meter 3x 1,5mm² | E82: 476
B83: 3001036 | C83: Wieland verlengkabel 2 meter 3x 1,5mm² | E83: 740
B84: 3001037 | C84: Wieland verlengkabel 3 meter 3x 1,5mm² | E84: 770
B85: 3001038 | C85: Wieland verlengkabel 5 meter 3x 1,5mm² | E85: 742
B86: 3001039 | C86: Wieland verlengkabel 7,5 meter 3x 1,5mm² | E86: 45
...

Sheet Q2 2025
A1: Evenement | B1: Artikelnr | C1: Omschrijving | D1: Besteld | E1: Stuksprijs | F1: Brutobedrag | G1: Bruto - Rel.korting | H1: Relatiekorting percentage | I1: Groep | J1: Artikelprijs | K1: Vergelijk | L1: Relatie korting | M1: Prijs 2 | N1: Brutobedrag 2 | O1: Bruto-Rel. korting 2
A2: Alpe du Huez Elektra - 2025.xls | B2: 5022022 | C2: Power supply 80 kW (incl. CEE 125A & Power Consumption) 2d | D2: 1 | E2: 1655.72 | F2: 1655.72 | G2: 1241.79 | H2: 25 | I2: =_xlfn.XLOOKUP(Q2_2025[[#This Row],[Artikelnr]],Artikel_prijzen[Artnr],Artikel_prijzen[Groep],"") -> Elektra | J2: =_xlfn.XLOOKUP(Q2_2025[[#This Row],[Artikelnr]],Artikel_prijzen[Artnr],Artikel_prijzen[Prijs 2025],"") -> 1100 | K2: =IF(Q2_2025[[#This Row],[Artikelprijs]]<>"",IF(Q2_2025[[#This Row],[Stuksprijs]]=Q2_2025[[#This Row],[Artikelprijs]],"Prijs gelijk","Prijs wijkt af"),"") -> Prijs wijkt af | L2: =IF(Q2_2025[[#This Row],[Relatiekorting percentage]]=0, "Nvt", IF(Q2_2025[[#This Row],[Brutobedrag 2]] < Q2_2025[[#This Row],[Bruto - Rel.korting]], "Nee", "Ja")) -> Nee | M2: =IF(Q2_2025[[#This Row],[Artikelprijs]]<>"",Q2_2025[[#This Row],[Artikelprijs]],Q2_2025[[#This Row],[Stuksprijs]]) -> 1100 | N2: =Q2_2025[[#This Row],[Besteld]]*Q2_2025[[#This Row],[Prijs 2]] -> 1100 | O2: =IF(Q2_2025[[#This Row],[Brutobedrag 2]]<Q2_2025[[#This Row],[Bruto - Rel.korting]],Q2_2025[[#This Row],[Brutobedrag 2]],Q2_2025[[#This Row],[Brutobedrag 2]]*(100-Q2_2025[[#This Row],[Relatiekorting percentage]])/100) -> 1100
A3: Alpe du Huez Elektra - 2025.xls | B3: 5022014 | C3: Power supply 9 kW (incl. CEE 32A & Power Consumption) 2d | D3: 1 | E3: 377.11 | F3: 377.11 | G3: 282.83 | H3: 25 | I3: =_xlfn.XLOOKUP(Q2_2025[[#This Row],[Artikelnr]],Artikel_prijzen[Artnr],Artikel_prijzen[Groep],"") -> Elektra | J3: =_xlfn.XLOOKUP(Q2_2025[[#This Row],[Artikelnr]],Artikel_prijzen[Artnr],Artikel_prijzen[Prijs 2025],"") -> 298.7 | K3: =IF(Q2_2025[[#This Row],[Artikelprijs]]<>"",IF(Q2_2025[[#This Row],[Stuksprijs]]=Q2_2025[[#This Row],[Artikelprijs]],"Prijs gelijk","Prijs wijkt af"),"") -> Prijs wijkt af | L3: =IF(Q2_2025[[#This Row],[Relatiekorting percentage]]=0, "Nvt", IF(Q2_2025[[#This Row],[Brutobedrag 2]] < Q2_2025[[#This Row],[Bruto - Rel.korting]], "Nee", "Ja")) -> Ja | M3: =IF(Q2_2025[[#This Row],[Artikelprijs]]<>"",Q2_2025[[#This Row],[Artikelprijs]],Q2_2025[[#This Row],[Stuksprijs]]) -> 298.7 | N3: =Q2_2025[[#This Row],[Besteld]]*Q2_2025[[#This Row],[Prijs 2]] -> 298.7 | O3: =IF(Q2_2025[[#This Row],[Brutobedrag 2]]<Q2_2025[[#This Row],[Bruto - Rel.korting]],Q2_2025[[#This Row],[Brutobedrag 2]],Q2_2025[[#This Row],[Brutobedrag 2]]*(100-Q2_2025[[#This Row],[Relatiekorting percentage]])/100) -> 224.025
A4: Alpe du Huez Elektra - 2025.xls | B4: 5022017 | C4: Power supply 20 kW (incl. CEE 32A & Power Consumption) 2d | D4: 1 | E4: 632.59 | F4: 632.59 | G4: 474.44 | H4: 25 | I4: =_xlfn.XLOOKUP(Q2_2025[[#This Row],[Artikelnr]],Artikel_prijzen[Artnr],Artikel_prijzen[Groep],"") -> Elektra | J4: =_xlfn.XLOOKUP(Q2_2025[[#This Row],[Artikelnr]],Artikel_prijzen[Artnr],Artikel_prijzen[Prijs 2025],"") -> 458.35 | K4: =IF(Q2_2025[[#This Row],[Artikelprijs]]<>"",IF(Q2_2025[[#This Row],[Stuksprijs]]=Q2_2025[[#This Row],[Artikelprijs]],"Prijs gelijk","Prijs wijkt af"),"") -> Prijs wijkt af | L4: =IF(Q2_2025[[#This Row],[Relatiekorting percentage]]=0, "Nvt", IF(Q2_2025[[#This Row],[Brutobedrag 2]] < Q2_2025[[#This Row],[Bruto - Rel.korting]], "Nee", "Ja")) -> Nee | M4: =IF(Q2_2025[[#This Row],[Artikelprijs]]<>"",Q2_2025[[#This Row],[Artikelprijs]],Q2_2025[[#This Row],[Stuksprijs]]) -> 458.35 | N4: =Q2_2025[[#This Row],[Besteld]]*Q2_2025[[#This Row],[Prijs 2]] -> 458.35 | O4: =IF(Q2_2025[[#This Row],[Brutobedrag 2]]<Q2_2025[[#This Row],[Bruto - Rel.korting]],Q2_2025[[#This Row],[Brutobedrag 2]],Q2_2025[[#This Row],[Brutobedrag 2]]*(100-Q2_2025[[#This Row],[Relatiekorting percentage]])/100) -> 458.35
A5: Alpe du Huez Elektra - 2025.xls | B5: 5021001 | C5: Stroomaansl. 3kW + WCD + Verbruik 1d | D5: 1 | E5: 154.5 | F5: 154.5 | G5: 115.87 | H5: 25 | I5: =_xlfn.XLOOKUP(Q2_2025[[#This Row],[Artikelnr]],Artikel_prijzen[Artnr],Artikel_prijzen[Groep],"") -> Elektra | J5: =_xlfn.XLOOKUP(Q2_2025[[#This Row],[Artikelnr]],Artikel_prijzen[Artnr],Artikel_prijzen[Prijs 2025],"") -> 106.8625 | K5: =IF(Q2_2025[[#This Row],[Artikelprijs]]<>"",IF(Q2_2025[[#This Row],[Stuksprijs]]=Q2_2025[[#This Row],[Artikelprijs]],"Prijs gelijk","Prijs wijkt af"),"") -> Prijs wijkt af | L5: =IF(Q2_2025[[#This Row],[Relatiekorting percentage]]=0, "Nvt", IF(Q2_2025[[#This Row],[Brutobedrag 2]] < Q2_2025[[#This Row],[Bruto - Rel.korting]], "Nee", "Ja")) -> Nee | M5: =IF(Q2_2025[[#This Row],[Artikelprijs]]<>"",Q2_2025[[#This Row],[Artikelprijs]],Q2_2025[[#This Row],[Stuksprijs]]) -> 106.8625 | N5: =Q2_2025[[#This Row],[Besteld]]*Q2_2025[[#This Row],[Prijs 2]] -> 106.8625 | O5: =IF(Q2_2025[[#This Row],[Brutobedrag 2]]<Q2_2025[[#This Row],[Bruto - Rel.korting]],Q2_2025[[#This Row],[Brutobedrag 2]],Q2_2025[[#This Row],[Brutobedrag 2]]*(100-Q2_2025[[#This Row],[Relatiekorting percentage]])/100) -> 106.8625
A6: Alpe du Huez Elektra - 2025.xls | B6: 5021001 | C6: Stroomaansl. 3kW + WCD + Verbruik 1d | D6: 1 | E6: 154.5 | F6: 154.5 | G6: 115.87 | H6: 25 | I6: =_xlfn.XLOOKUP(Q2_2025[[#This Row],[Artikelnr]],Artikel_prijzen[Artnr],Artikel_prijzen[Groep],"") -> Elektra | J6: =_xlfn.XLOOKUP(Q2_2025[[#This Row],[Artikelnr]],Artikel_prijzen[Artnr],Artikel_prijzen[Prijs 2025],"") -> 106.8625 | K6: =IF(Q2_2025[[#This Row],[Artikelprijs]]<>"",IF(Q2_2025[[#This Row],[Stuksprijs]]=Q2_2025[[#This Row],[Artikelprijs]],"Prijs gelijk","Prijs wijkt af"),"") -> Prijs wijkt af | L6: =IF(Q2_2025[[#This Row],[Relatiekorting percentage]]=0, "Nvt", IF(Q2_2025[[#This Row],[Brutobedrag 2]] < Q2_2025[[#This Row],[Bruto - Rel.korting]], "Nee", "Ja")) -> Nee | M6: =IF(Q2_2025[[#This Row],[Artikelprijs]]<>"",Q2_2025[[#This Row],[Artikelprijs]],Q2_2025[[#This Row],[Stuksprijs]]) -> 106.8625 | N6: =Q2_2025[[#This Row],[Besteld]]*Q2_2025[[#This Row],[Prijs 2]] -> 106.8625 | O6: =IF(Q2_2025[[#This Row],[Brutobedrag 2]]<Q2_2025[[#This Row],[Bruto - Rel.korting]],Q2_2025[[#This Row],[Brutobedrag 2]],Q2_2025[[#This Row],[Brutobedrag 2]]*(100-Q2_2025[[#This Row],[Relatiekorting percentage]])/100) -> 106.8625
A7: Alpe du Huez Elektra - 2025.xls | B7: 5021001 | C7: Stroomaansl. 3kW + WCD + Verbruik 1d | D7: 4 | E7: 154.5 | F7: 618 | G7: 463.5 | H7: 25 | I7: =_xlfn.XLOOKUP(Q2_2025[[#This Row],[Artikelnr]],Artikel_prijzen[Artnr],Artikel_prijzen[Groep],"") -> Elektra | J7: =_xlfn.XLOOKUP(Q2_2025[[#This Row],[Artikelnr]],Artikel_prijzen[Artnr],Artikel_prijzen[Prijs 2025],"") -> 106.8625 | K7: =IF(Q2_2025[[#This Row],[Artikelprijs]]<>"",IF(Q2_2025[[#This Row],[Stuksprijs]]=Q2_2025[[#This Row],[Artikelprijs]],"Prijs gelijk","Prijs wijkt af"),"") -> Prijs wijkt af | L7: =IF(Q2_2025[[#This Row],[Relatiekorting percentage]]=0, "Nvt", IF(Q2_2025[[#This Row],[Brutobedrag 2]] < Q2_2025[[#This Row],[Bruto - Rel.korting]], "Nee", "Ja")) -> Nee | M7: =IF(Q2_2025[[#This Row],[Artikelprijs]]<>"",Q2_2025[[#This Row],[Artikelprijs]],Q2_2025[[#This Row],[Stuksprijs]]) -> 106.8625 | N7: =Q2_2025[[#This Row],[Besteld]]*Q2_2025[[#This Row],[Prijs 2]] -> 427.45 | O7: =IF(Q2_2025[[#This Row],[Brutobedrag 2]]<Q2_2025[[#This Row],[Bruto - Rel.korting]],Q2_2025[[#This Row],[Brutobedrag 2]],Q2_2025[[#This Row],[Brutobedrag 2]]*(100-Q2_2025[[#This Row],[Relatiekorting percentage]])/100) -> 427.45
